Workbook

Sheet Read_Me
A1: GRC102 Week 3 – NDPC Security Governance Data Pack
A3: Purpose
A4: This workbook contains a simulated security incident dataset for the National Digital Protection Corporation (NDPC). It is provided for academic analysis in GRC102. Students should use the Incident_Data sheet to perform independent analysis, create appropriate visualisations, and connect findings to governance roles, accountability, escalation and control effectiveness.
A8: Dataset status | B8: Simulated / fictional academic dataset
A9: Records | B9: 180
A10: Historical period | B10: 2024–2025
A11: Original records retained | B11: 100
A12: Additional simulated records | B12: 80
A13: Primary worksheet | B13: Incident_Data
A14: Supporting worksheets | B14: Data_Dictionary; Analysis_Template
A16: Academic Integrity Note
A17: Do not treat this dataset as real organisational evidence. Calculations, charts, interpretations and recommendations must be your own work. If AI tools are used, verify all calculations and declare material assistance in accordance with the assignment brief.

Sheet Incident_Data
A1: Incident_ID | B1: Date | C1: Incident_Type | D1: Severity | E1: Status | F1: Department | G1: Responsible_Team | H1: Resolution_Time_Days | I1: Cost_Impact_USD | J1: Root_Cause | K1: Control_Domain | L1: Regulatory_Exposure | M1: Escalation_Level | N1: Third_Party_Involved | O1: SLA_Target_Days | P1: SLA_Breached
A2: INC0001 | B2: 45428 | C2: Malware | D2: Medium | E2: Open | F2: Operations | G2: Compliance | H2: 16 | I2: 94101 | J2: Malicious attachment | K2: Endpoint Security | L2: Contractual | M2: CISO / Department Head | N2: No | O2: 14 | P2: Pending
A3: INC0002 | B3: 45432 | C3: Misconfiguration | D3: High | E3: On Hold | F3: Finance | G3: Compliance | H3: 17 | I3: 85119 | J3: Access rule misconfiguration | K3: Configuration Management | L3: None | M3: Executive / CISO | N3: Yes | O3: 7 | P3: Pending
A4: INC0003 | B4: 45653 | C4: Malware | D4: High | E4: Closed | F4: HR | G4: IT Security | H4: 8 | I4: 99720 | J4: Unsafe software installation | K4: Endpoint Security | L4: None | M4: Executive / CISO | N4: No | O4: 7 | P4: Yes
A5: INC0004 | B5: 45405 | C5: Malware | D5: High | E5: Closed | F5: HR | G5: SOC | H5: 13 | I5: 80858 | J5: Malicious attachment | K5: Endpoint Security | L5: None | M5: Executive / CISO | N5: No | O5: 7 | P5: Yes
A6: INC0005 | B6: 45348 | C6: DDoS | D6: High | E6: Closed | F6: Finance | G6: IT Security | H6: 26 | I6: 14076 | J6: Capacity planning gap | K6: Network Resilience | L6: Financial Data | M6: Executive / CISO | N6: No | O6: 7 | P6: Yes
A7: INC0006 | B7: 45321 | C7: DDoS | D7: Low | E7: Closed | F7: Operations | G7: SOC | H7: 27 | I7: 67086 | J7: Insufficient rate limiting | K7: Network Resilience | L7: Operational | M7: Operational | N7: No | O7: 30 | P7: No
A8: INC0007 | B8: 45430 | C8: Phishing | D8: High | E8: Closed | F8: Finance | G8: SOC | H8: 23 | I8: 41743 | J8: Spoofed business email | K8: Security Awareness | L8: Privacy | M8: Executive / CISO | N8: No | O8: 7 | P8: Yes
A9: INC0008 | B9: 45342 | C9: Unauthorized Access | D9: Low | E9: Closed | F9: HR | G9: Compliance | H9: 13 | I9: 64337 | J9: Excessive privileges | K9: Identity & Access Management | L9: Privacy | M9: Operational | N9: No | O9: 30 | P9: No
A10: INC0009 | B10: 45558 | C10: DDoS | D10: Medium | E10: In Progress | F10: HR | G10: Compliance | H10: 10 | I10: 96050 | J10: Insufficient rate limiting | K10: Network Resilience | L10: None | M10: CISO / Department Head | N10: No | O10: 14 | P10: Pending
A11: INC0010 | B11: 45310 | C11: Phishing | D11: High | E11: Open | F11: Finance | G11: Compliance | H11: 12 | I11: 24146 | J11: Credential harvesting | K11: Security Awareness | L11: Financial Data | M11: Executive / CISO | N11: No | O11: 7 | P11: Pending
A12: INC0011 | B12: 45649 | C12: Data Leak | D12: High | E12: Closed | F12: Finance | G12: SOC | H12: 21 | I12: 95926 | J12: Data handling error | K12: Data Protection | L12: Privacy | M12: Executive / CISO | N12: Yes | O12: 7 | P12: Yes
A13: INC0012 | B13: 45300 | C13: Data Leak | D13: Medium | E13: Closed | F13: IT | G13: SOC | H13: 17 | I13: 3268 | J13: Data handling error | K13: Data Protection | L13: None | M13: CISO / Department Head | N13: No | O13: 14 | P13: Yes
... A181: INC0180 | B181: 45819 | C181: Misconfiguration | D181: High | E181: Closed | F181: Operations | G181: DevOps | H181: 10 | I181: 40880 | J181: Change-control failure | K181: Configuration Management | L181: Operational | M181: Executive / CISO | N181: No | O181: 7 | P181: Yes

Sheet Data_Dictionary
A1: Field | B1: Description | C1: Example / Values
A2: Incident_ID | B2: Unique simulated incident identifier. | C2: INC0001
A3: Date | B3: Date on which the incident was recorded. | C3: 2025-03-17
A4: Incident_Type | B4: Primary incident category. | C4: Malware, Phishing, Data Leak, Cloud Exposure, etc.
A5: Severity | B5: Business/security severity assigned to the incident. | C5: Low, Medium, High, Critical
A6: Status | B6: Current incident state. | C6: Closed, In Progress, Open, On Hold
A7: Department | B7: Business unit most directly affected. | C7: Finance, HR, IT, Operations, etc.
A8: Responsible_Team | B8: Team accountable for coordinating the response. | C8: SOC, IT Security, GRC, IAM, Cloud Security, etc.
A9: Resolution_Time_Days | B9: Days taken to resolve a closed incident or elapsed days recorded for an unresolved incident. | C9: 1–30+
A10: Cost_Impact_USD | B10: Estimated direct and indirect cost impact in US dollars. | C10: 25000
A11: Root_Cause | B11: Primary contributing root-cause category. | C11: Compromised credentials, Change-control failure, etc.
A12: Control_Domain | B12: Governance/control domain associated with the incident. | C12: Identity & Access Management, Data Protection, etc.
... A17: SLA_Breached | B17: Whether a closed incident exceeded the simulated resolution SLA; unresolved incidents are Pending. | C17: Yes / No / Pending

Sheet Analysis_Template
A1: GRC102 Week 3 Student Analysis Template
A2: Use this sheet as a planning workspace. Do not submit it as a substitute for the written assignment unless instructed.
A3: Analysis Requirement | B3: Your Notes / Result
A4: Total number of incidents | B4: 180 (see Core_Analysis!B5)
A5: Distribution by Incident_Type | B5: See Core_Analysis, Section 2 table and chart
A6: Average Resolution_Time_Days by Severity | B6: See Core_Analysis, Section 3 table
A7: Total Cost_Impact_USD by Department | B7: See Core_Analysis, Section 4 table and chart
A8: Total Cost_Impact_USD by Responsible_Team | B8: See Core_Analysis, Section 5 table
A9: Top 3 Incident_Type categories by average Cost_Impact_USD | B9: Insider Threat, Cloud Exposure, Third-Party Breach — see Core_Analysis, Section 6 (ranked)
A10: Percentage of incidents that are Open or In Progress | B10: 25.6% — see Core_Analysis, Section 7
A11: SLA breach pattern by Severity / Responsible_Team (advanced) | B11: See Advanced_Analysis, Tables 1-2
A12: Regulatory exposure trends (advanced) | B12: See Advanced_Analysis, Table 3
A13: Third-party involvement trends (advanced) | B13: See Advanced_Analysis, Table 4
A14: Most important governance insight #1 | B14: IAM SLA breaches drive risk; see CISO_Board_Insights #1
... A19: Governance recommendation #3 | B19: See CISO_Board_Insights row 3, recommended action

Sheet Core_Analysis
A1: GRC102 Week 3 — Part D1: Core NDPC Incident Analysis
A2: All figures below are computed live from the Incident_Data sheet using formulas (COUNT/SUM/AVERAGEIF family). Re-run if source data changes.
A4: 1. Total number of incidents
A5: Total incidents (Incident_Data row count) | B5: =COUNTA(Incident_Data!$A$2:$A$181) -> 180
A7: 2. Distribution of incidents by Incident_Type
A8: Incident_Type | B8: Count | C8: % of Total
A9: Malware | B9: =COUNTIF(Incident_Data!$C$2:$C$181,A9) -> 28 | C9: =B9/$B$5 -> 0.15555556
A10: Phishing | B10: =COUNTIF(Incident_Data!$C$2:$C$181,A10) -> 28 | C10: =B10/$B$5 -> 0.15555556
A11: Data Leak | B11: =COUNTIF(Incident_Data!$C$2:$C$181,A11) -> 27 | C11: =B11/$B$5 -> 0.15
A12: Unauthorized Access | B12: =COUNTIF(Incident_Data!$C$2:$C$181,A12) -> 24 | C12: =B12/$B$5 -> 0.13333333
A13: Misconfiguration | B13: =COUNTIF(Incident_Data!$C$2:$C$181,A13) -> 19 | C13: =B13/$B$5 -> 0.10555556
A14: DDoS | B14: =COUNTIF(Incident_Data!$C$2:$C$181,A14) -> 19 | C14: =B14/$B$5 -> 0.10555556
A15: Cloud Exposure | B15: =COUNTIF(Incident_Data!$C$2:$C$181,A15) -> 11 | C15: =B15/$B$5 -> 0.061111111
A16: Credential Theft | B16: =COUNTIF(Incident_Data!$C$2:$C$181,A16) -> 9 | C16: =B16/$B$5 -> 0.05
A17: Third-Party Breach | B17: =COUNTIF(Incident_Data!$C$2:$C$181,A17) -> 6 | C17: =B17/$B$5 -> 0.033333333
A18: Insider Threat | B18: =COUNTIF(Incident_Data!$C$2:$C$181,A18) -> 5 | C18: =B18/$B$5 -> 0.027777778
A19: Lost Device | B19: =COUNTIF(Incident_Data!$C$2:$C$181,A19) -> 3 | C19: =B19/$B$5 -> 0.016666667
A20: Policy Violation | B20: =COUNTIF(Incident_Data!$C$2:$C$181,A20) -> 1 | C20: =B20/$B$5 -> 0.0055555556
A22: 3. Average Resolution_Time_Days by Severity
A23: Severity | B23: Avg Resolution Days | C23: Incident Count
A24: Critical | B24: =AVERAGEIF(Incident_Data!$D$2:$D$181,A24,Incident_Data!$H$2:$H$181) -> 9.8 | C24: =COUNTIF(Incident_Data!$D$2:$D$181,A24) -> 20
A25: High | B25: =AVERAGEIF(Incident_Data!$D$2:$D$181,A25,Incident_Data!$H$2:$H$181) -> 12.716981 | C25: =COUNTIF(Incident_Data!$D$2:$D$181,A25) -> 53
A26: Medium | B26: =AVERAGEIF(Incident_Data!$D$2:$D$181,A26,Incident_Data!$H$2:$H$181) -> 14.7375 | C26: =COUNTIF(Incident_Data!$D$2:$D$181,A26) -> 80
A27: Low | B27: =AVERAGEIF(Incident_Data!$D$2:$D$181,A27,Incident_Data!$H$2:$H$181) -> 18.148148 | C27: =COUNTIF(Incident_Data!$D$2:$D$181,A27) -> 27
A50: 4. Total Cost_Impact_USD by Department
A51: Department | B51: Total Cost Impact (USD)
A52: Finance | B52: =SUMIF(Incident_Data!$F$2:$F$181,A52,Incident_Data!$I$2:$I$181) -> 1756282
A53: IT | B53: =SUMIF(Incident_Data!$F$2:$F$181,A53,Incident_Data!$I$2:$I$181) -> 1725965
A54: Operations | B54: =SUMIF(Incident_Data!$F$2:$F$181,A54,Incident_Data!$I$2:$I$181) -> 1682059
A55: HR | B55: =SUMIF(Incident_Data!$F$2:$F$181,A55,Incident_Data!$I$2:$I$181) -> 1493242
A56: Legal | B56: =SUMIF(Incident_Data!$F$2:$F$181,A56,Incident_Data!$I$2:$I$181) -> 1403244
A57: Cloud Operations | B57: =SUMIF(Incident_Data!$F$2:$F$181,A57,Incident_Data!$I$2:$I$181) -> 663410
A58: Student Services | B58: =SUMIF(Incident_Data!$F$2:$F$181,A58,Incident_Data!$I$2:$I$181) -> 643730
A59: Academic Services | B59: =SUMIF(Incident_Data!$F$2:$F$181,A59,Incident_Data!$I$2:$I$181) -> 617870
A60: Research | B60: =SUMIF(Incident_Data!$F$2:$F$181,A60,Incident_Data!$I$2:$I$181) -> 307620
A62: 5. Total Cost_Impact_USD by Responsible_Team
A63: Responsible_Team | B63: Total Cost Impact (USD)
A64: Compliance | B64: =SUMIF(Incident_Data!$G$2:$G$181,A64,Incident_Data!$I$2:$I$181) -> 2836299
A65: DevOps | B65: =SUMIF(Incident_Data!$G$2:$G$181,A65,Incident_Data!$I$2:$I$181) -> 2079986
A66: IT Security | B66: =SUMIF(Incident_Data!$G$2:$G$181,A66,Incident_Data!$I$2:$I$181) -> 1763143
...

Sheet Advanced_Analysis
A1: GRC102 Week 3 — Part D2: Advanced Governance Analysis
A2: SLA breach rate is calculated only over incidents with a determined SLA outcome (SLA_Breached = Yes/No); 'Pending' (still open) incidents are excluded from the denominator, consistent with the Data_Dictionary definition.
A4: 1. SLA_Breached pattern by Severity (resolved incidents only)
A5: Severity | B5: Breached (Yes) | C5: Not Breached (No) | D5: Resolved Total | E5: Breach Rate %
A6: Critical | B6: =COUNTIFS(Incident_Data!$D$2:$D$181,A6,Incident_Data!$P$2:$P$181,"Yes") -> 12 | C6: =COUNTIFS(Incident_Data!$D$2:$D$181,A6,Incident_Data!$P$2:$P$181,"No") -> 5 | D6: =B6+C6 -> 17 | E6: =IF(D6=0,0,B6/D6) -> 0.70588235
A7: High | B7: =COUNTIFS(Incident_Data!$D$2:$D$181,A7,Incident_Data!$P$2:$P$181,"Yes") -> 25 | C7: =COUNTIFS(Incident_Data!$D$2:$D$181,A7,Incident_Data!$P$2:$P$181,"No") -> 9 | D7: =B7+C7 -> 34 | E7: =IF(D7=0,0,B7/D7) -> 0.73529412
A8: Medium | B8: =COUNTIFS(Incident_Data!$D$2:$D$181,A8,Incident_Data!$P$2:$P$181,"Yes") -> 17 | C8: =COUNTIFS(Incident_Data!$D$2:$D$181,A8,Incident_Data!$P$2:$P$181,"No") -> 32 | D8: =B8+C8 -> 49 | E8: =IF(D8=0,0,B8/D8) -> 0.34693878
A9: Low | B9: =COUNTIFS(Incident_Data!$D$2:$D$181,A9,Incident_Data!$P$2:$P$181,"Yes") -> 0 | C9: =COUNTIFS(Incident_Data!$D$2:$D$181,A9,Incident_Data!$P$2:$P$181,"No") -> 17 | D9: =B9+C9 -> 17 | E9: =IF(D9=0,0,B9/D9) -> 0
A11: 2. SLA_Breached pattern by Responsible_Team (resolved incidents only)
A12: Responsible_Team | B12: Breached (Yes) | C12: Not Breached (No) | D12: Resolved Total | E12: Breach Rate %
A13: Compliance | B13: =COUNTIFS(Incident_Data!$G$2:$G$181,A13,Incident_Data!$P$2:$P$181,"Yes") -> 8 | C13: =COUNTIFS(Incident_Data!$G$2:$G$181,A13,Incident_Data!$P$2:$P$181,"No") -> 14 | D13: =B13+C13 -> 22 | E13: =IF(D13=0,0,B13/D13) -> 0.36363636
A14: DevOps | B14: =COUNTIFS(Incident_Data!$G$2:$G$181,A14,Incident_Data!$P$2:$P$181,"Yes") -> 13 | C14: =COUNTIFS(Incident_Data!$G$2:$G$181,A14,Incident_Data!$P$2:$P$181,"No") -> 12 | D14: =B14+C14 -> 25 | E14: =IF(D14=0,0,B14/D14) -> 0.52
A15: IT Security | B15: =COUNTIFS(Incident_Data!$G$2:$G$181,A15,Incident_Data!$P$2:$P$181,"Yes") -> 15 | C15: =COUNTIFS(Incident_Data!$G$2:$G$181,A15,Incident_Data!$P$2:$P$181,"No") -> 9 | D15: =B15+C15 -> 24 | E15: =IF(D15=0,0,B15/D15) -> 0.625
A16: SOC | B16: =COUNTIFS(Incident_Data!$G$2:$G$181,A16,Incident_Data!$P$2:$P$181,"Yes") -> 11 | C16: =COUNTIFS(Incident_Data!$G$2:$G$181,A16,Incident_Data!$P$2:$P$181,"No") -> 13 | D16: =B16+C16 -> 24 | E16: =IF(D16=0,0,B16/D16) -> 0.45833333
A17: GRC | B17: =COUNTIFS(Incident_Data!$G$2:$G$181,A17,Incident_Data!$P$2:$P$181,"Yes") -> 4 | C17: =COUNTIFS(Incident_Data!$G$2:$G$181,A17,Incident_Data!$P$2:$P$181,"No") -> 5 | D17: =B17+C17 -> 9 | E17: =IF(D17=0,0,B17/D17) -> 0.44444444
A18: Incident Response | B18: =COUNTIFS(Incident_Data!$G$2:$G$181,A18,Incident_Data!$P$2:$P$181,"Yes") -> 1 | C18: =COUNTIFS(Incident_Data!$G$2:$G$181,A18,Incident_Data!$P$2:$P$181,"No") -> 9 | D18: =B18+C18 -> 10 | E18: =IF(D18=0,0,B18/D18) -> 0.1
A19: IAM | B19: =COUNTIFS(Incident_Data!$G$2:$G$181,A19,Incident_Data!$P$2:$P$181,"Yes") -> 1 | C19: =COUNTIFS(Incident_Data!$G$2:$G$181,A19,Incident_Data!$P$2:$P$181,"No") -> 0 | D19: =B19+C19 -> 1 | E19: =IF(D19=0,0,B19/D19) -> 1
A20: Cloud Security | B20: =COUNTIFS(Incident_Data!$G$2:$G$181,A20,Incident_Data!$P$2:$P$181,"Yes") -> 1 | C20: =COUNTIFS(Incident_Data!$G$2:$G$181,A20,Incident_Data!$P$2:$P$181,"No") -> 1 | D20: =B20+C20 -> 2 | E20: =IF(D20=0,0,B20/D20) -> 0.5
A22: 3. Regulatory_Exposure pattern by Department (count of incidents per exposure category)
A23: Department | B23: Privacy | C23: Contractual | D23: Financial Data | E23: Operational | F23: Regulatory | G23: Education Records | H23: Employment Data | I23: Research Data | J23: None
A24: Finance | B24: =COUNTIFS(Incident_Data!$F$2:$F$181,$A24,Incident_Data!$L$2:$L$181,B$23) -> 9 | C24: =COUNTIFS(Incident_Data!$F$2:$F$181,$A24,Incident_Data!$L$2:$L$181,C$23) -> 0 | D24: =COUNTIFS(Incident_Data!$F$2:$F$181,$A24,Incident_Data!$L$2:$L$181,D$23) -> 14 | E24: =COUNTIFS(Incident_Data!$F$2:$F$181,$A24,Incident_Data!$L$2:$L$181,E$23) -> 0 | F24: =COUNTIFS(Incident_Data!$F$2:$F$181,$A24,Incident_Data!$L$2:$L$181,F$23) -> 0 | G24: =COUNTIFS(Incident_Data!$F$2:$F$181,$A24,Incident_Data!$L$2:$L$181,G$23) -> 0 | H24: =COUNTIFS(Incident_Data!$F$2:$F$181,$A24,Incident_Data!$L$2:$L$181,H$23) -> 0 | I24: =COUNTIFS(Incident_Data!$F$2:$F$181,$A24,Incident_Data!$L$2:$L$181,I$23) -> 0 | J24: =COUNTIFS(Incident_Data!$F$2:$F$181,$A24,Incident_Data!$L$2:$L$181,"") -> 0
A25: IT | B25: =COUNTIFS(Incident_Data!$F$2:$F$181,$A25,Incident_Data!$L$2:$L$181,B$23) -> 14 | C25: =COUNTIFS(Incident_Data!$F$2:$F$181,$A25,Incident_Data!$L$2:$L$181,C$23) -> 8 | D25: =COUNTIFS(Incident_Data!$F$2:$F$181,$A25,Incident_Data!$L$2:$L$181,D$23) -> 0 | E25: =COUNTIFS(Incident_Data!$F$2:$F$181,$A25,Incident_Data!$L$2:$L$181,E$23) -> 0 | F25: =COUNTIFS(Incident_Data!$F$2:$F$181,$A25,Incident_Data!$L$2:$L$181,F$23) -> 0 | G25: =COUNTIFS(Incident_Data!$F$2:$F$181,$A25,Incident_Data!$L$2:$L$181,G$23) -> 0 | H25: =COUNTIFS(Incident_Data!$F$2:$F$181,$A25,Incident_Data!$L$2:$L$181,H$23) -> 0 | I25: =COUNTIFS(Incident_Data!$F$2:$F$181,$A25,Incident_Data!$L$2:$L$181,I$23) -> 0 | J25: =COUNTIFS(Incident_Data!$F$2:$F$181,$A25,Incident_Data!$L$2:$L$181,"") -> 0
A26: Operations | B26: =COUNTIFS(Incident_Data!$F$2:$F$181,$A26,Incident_Data!$L$2:$L$181,B$23) -> 0 | C26: =COUNTIFS(Incident_Data!$F$2:$F$181,$A26,Incident_Data!$L$2:$L$181,C$23) -> 13 | D26: =COUNTIFS(Incident_Data!$F$2:$F$181,$A26,Incident_Data!$L$2:$L$181,D$23) -> 0 | E26: =COUNTIFS(Incident_Data!$F$2:$F$181,$A26,Incident_Data!$L$2:$L$181,E$23) -> 9 | F26: =COUNTIFS(Incident_Data!$F$2:$F$181,$A26,Incident_Data!$L$2:$L$181,F$23) -> 0 | G26: =COUNTIFS(Incident_Data!$F$2:$F$181,$A26,Incident_Data!$L$2:$L$181,G$23) -> 0 | H26: =COUNTIFS(Incident_Data!$F$2:$F$181,$A26,Incident_Data!$L$2:$L$181,H$23) -> 0 | I26: =COUNTIFS(Incident_Data!$F$2:$F$181,$A26,Incident_Data!$L$2:$L$181,I$23) -> 0 | J26: =COUNTIFS(Incident_Data!$F$2:$F$181,$A26,Incident_Data!$L$2:$L$181,"") -> 0
A27: HR | B27: =COUNTIFS(Incident_Data!$F$2:$F$181,$A27,Incident_Data!$L$2:$L$181,B$23) -> 9 | C27: =COUNTIFS(Incident_Data!$F$2:$F$181,$A27,Incident_Data!$L$2:$L$181,C$23) -> 0 | D27: =COUNTIFS(Incident_Data!$F$2:$F$181,$A27,Incident_Data!$L$2:$L$181,D$23) -> 0 | E27: =COUNTIFS(Incident_Data!$F$2:$F$181,$A27,Incident_Data!$L$2:$L$181,E$23) -> 0 | F27: =COUNTIFS(Incident_Data!$F$2:$F$181,$A27,Incident_Data!$L$2:$L$181,F$23) -> 0 | G27: =COUNTIFS(Incident_Data!$F$2:$F$181,$A27,Incident_Data!$L$2:$L$181,G$23) -> 0 | H27: =COUNTIFS(Incident_Data!$F$2:$F$181,$A27,Incident_Data!$L$2:$L$181,H$23) -> 4 | I27: =COUNTIFS(Incident_Data!$F$2:$F$181,$A27,Incident_Data!$L$2:$L$181,I$23) -> 0 | J27: =COUNTIFS(Incident_Data!$F$2:$F$181,$A27,Incident_Data!$L$2:$L$181,"") -> 0
A28: Legal | B28: =COUNTIFS(Incident_Data!$F$2:$F$181,$A28,Incident_Data!$L$2:$L$181,B$23) -> 10 | C28: =COUNTIFS(Incident_Data!$F$2:$F$181,$A28,Incident_Data!$L$2:$L$181,C$23) -> 6 | D28: =COUNTIFS(Incident_Data!$F$2:$F$181,$A28,Incident_Data!$L$2:$L$181,D$23) -> 0 | E28: =COUNTIFS(Incident_Data!$F$2:$F$181,$A28,Incident_Data!$L$2:$L$181,E$23) -> 0 | F28: =COUNTIFS(Incident_Data!$F$2:$F$181,$A28,Incident_Data!$L$2:$L$181,F$23) -> 10 | G28: =COUNTIFS(Incident_Data!$F$2:$F$181,$A28,Incident_Data!$L$2:$L$181,G$23) -> 0 | H28: =COUNTIFS(Incident_Data!$F$2:$F$181,$A28,Incident_Data!$L$2:$L$181,H$23) -> 0 | I28: =COUNTIFS(Incident_Data!$F$2:$F$181,$A28,Incident_Data!$L$2:$L$181,I$23) -> 0 | J28: =COUNTIFS(Incident_Data!$F$2:$F$181,$A28,Incident_Data!$L$2:$L$181,"") -> 0
A29: Cloud Operations | B29: =COUNTIFS(Incident_Data!$F$2:$F$181,$A29,Incident_Data!$L$2:$L$181,B$23) -> 3 | C29: =COUNTIFS(Incident_Data!$F$2:$F$181,$A29,Incident_Data!$L$2:$L$181,C$23) -> 4 | D29: =COUNTIFS(Incident_Data!$F$2:$F$181,$A29,Incident_Data!$L$2:$L$181,D$23) -> 0 | E29: =COUNTIFS(Incident_Data!$F$2:$F$181,$A29,Incident_Data!$L$2:$L$181,E$23) -> 3 | F29: =COUNTIFS(Incident_Data!$F$2:$F$181,$A29,Incident_Data!$L$2:$L$181,F$23) -> 0 | G29: =COUNTIFS(Incident_Data!$F$2:$F$181,$A29,Incident_Data!$L$2:$L$181,G$23) -> 0 | H29: =COUNTIFS(Incident_Data!$F$2:$F$181,$A29,Incident_Data!$L$2:$L$181,H$23) -> 0 | I29: =COUNTIFS(Incident_Data!$F$2:$F$181,$A29,Incident_Data!$L$2:$L$181,I$23) -> 0 | J29: =COUNTIFS(Incident_Data!$F$2:$F$181,$A29,Incident_Data!$L$2:$L$181,"") -> 0
A30: Student Services | B30: =COUNTIFS(Incident_Data!$F$2:$F$181,$A30,Incident_Data!$L$2:$L$181,B$23) -> 3 | C30: =COUNTIFS(Incident_Data!$F$2:$F$181,$A30,Incident_Data!$L$2:$L$181,C$23) -> 0 | D30: =COUNTIFS(Incident_Data!$F$2:$F$181,$A30,Incident_Data!$L$2:$L$181,D$23) -> 0 | E30: =COUNTIFS(Incident_Data!$F$2:$F$181,$A30,Incident_Data!$L$2:$L$181,E$23) -> 0 | F30: =COUNTIFS(Incident_Data!$F$2:$F$181,$A30,Incident_Data!$L$2:$L$181,F$23) -> 0 | G30: =COUNTIFS(Incident_Data!$F$2:$F$181,$A30,Incident_Data!$L$2:$L$181,G$23) -> 4 | H30: =COUNTIFS(Incident_Data!$F$2:$F$181,$A30,Incident_Data!$L$2:$L$181,H$23) -> 0 | I30: =COUNTIFS(Incident_Data!$F$2:$F$181,$A30,Incident_Data!$L$2:$L$181,I$23) -> 0 | J30: =COUNTIFS(Incident_Data!$F$2:$F$181,$A30,Incident_Data!$L$2:$L$181,"") -> 0
A31: Academic Services | B31: =COUNTIFS(Incident_Data!$F$2:$F$181,$A31,Incident_Data!$L$2:$L$181,B$23) -> 5 | C31: =COUNTIFS(Incident_Data!$F$2:$F$181,$A31,Incident_Data!$L$2:$L$181,C$23) -> 0 | D31: =COUNTIFS(Incident_Data!$F$2:$F$181,$A31,Incident_Data!$L$2:$L$181,D$23) -> 0 | E31: =COUNTIFS(Incident_Data!$F$2:$F$181,$A31,Incident_Data!$L$2:$L$181,E$23) -> 0 | F31: =COUNTIFS(Incident_Data!$F$2:$F$181,$A31,Incident_Data!$L$2:$L$181,F$23) -> 0 | G31: =COUNTIFS(Incident_Data!$F$2:$F$181,$A31,Incident_Data!$L$2:$L$181,G$23) -> 2 | H31: =COUNTIFS(Incident_Data!$F$2:$F$181,$A31,Incident_Data!$L$2:$L$181,H$23) -> 0 | I31: =COUNTIFS(Incident_Data!$F$2:$F$181,$A31,Incident_Data!$L$2:$L$181,I$23) -> 0 | J31: =COUNTIFS(Incident_Data!$F$2:$F$181,$A31,Incident_Data!$L$2:$L$181,"") -> 0
A32: Research | B32: =COUNTIFS(Incident_Data!$F$2:$F$181,$A32,Incident_Data!$L$2:$L$181,B$23) -> 3 | C32: =COUNTIFS(Incident_Data!$F$2:$F$181,$A32,Incident_Data!$L$2:$L$181,C$23) -> 2 | D32: =COUNTIFS(Incident_Data!$F$2:$F$181,$A32,Incident_Data!$L$2:$L$181,D$23) -> 0 | E32: =COUNTIFS(Incident_Data!$F$2:$F$181,$A32,Incident_Data!$L$2:$L$181,E$23) -> 0 | F32: =COUNTIFS(Incident_Data!$F$2:$F$181,$A32,Incident_Data!$L$2:$L$181,F$23) -> 0 | G32: =COUNTIFS(Incident_Data!$F$2:$F$181,$A32,Incident_Data!$L$2:$L$181,G$23) -> 0 | H32: =COUNTIFS(Incident_Data!$F$2:$F$181,$A32,Incident_Data!$L$2:$L$181,H$23) -> 0 | I32: =COUNTIFS(Incident_Data!$F$2:$F$181,$A32,Incident_Data!$L$2:$L$181,I$23) -> 1 | J32: =COUNTIFS(Incident_Data!$F$2:$F$181,$A32,Incident_Data!$L$2:$L$181,"") -> 0
A34: 4. Third-party involvement — severity, cost and escalation association
A35: Third_Party_Involved | B35: Incident Count | C35: Average Cost Impact (USD) | D35: Critical/High Count | E35: Critical/High % | F35: Board/Executive Escalations
A36: Yes | B36: =COUNTIF(Incident_Data!$N$2:$N$181,A36) -> 43 | C36: =AVERAGEIF(Incident_Data!$N$2:$N$181,A36,Incident_Data!$I$2:$I$181) -> 73699.698 | D36: =COUNTIFS(Incident_Data!$N$2:$N$181,A36,Incident_Data!$D$2:$D$181,"Critical")+COUNTIFS(Incident_Data!$N$2:$N$181,A36,Incident_Data!$D$2:$D$181,"High") -> 18 | E36: =D36/B36 -> 0.41860465 | F36: =COUNTIFS(Incident_Data!$N$2:$N$181,A36,Incident_Data!$M$2:$M$181,"Board / Executive") -> 6
A37: No | B37: =COUNTIF(Incident_Data!$N$2:$N$181,A37) -> 137 | C37: =AVERAGEIF(Incident_Data!$N$2:$N$181,A37,Incident_Data!$I$2:$I$181) -> 52002.445 | D37: =COUNTIFS(Incident_Data!$N$2:$N$181,A37,Incident_Data!$D$2:$D$181,"Critical")+COUNTIFS(Incident_Data!$N$2:$N$181,A37,Incident_Data!$D$2:$D$181,"High") -> 55 | E37: =D37/B37 -> 0.40145985 | F37: =COUNTIFS(Incident_Data!$N$2:$N$181,A37,Incident_Data!$M$2:$M$181,"Board / Executive") -> 14
A39: 5. Control_Domain governance-attention scorecard
A40: Control_Domain | B40: Incident Count | C40: Total Cost (USD) | D40: Average Cost (USD) | E40: Critical/High % | F40: SLA Breach Rate % (resolved)
A41: Identity & Access Management | B41: =COUNTIF(Incident_Data!$K$2:$K$181,A41) -> 33 | C41: =SUMIF(Incident_Data!$K$2:$K$181,A41,Incident_Data!$I$2:$I$181) -> 1932469 | D41: =IF(B41=0,0,C41/B41) -> 58559.667 | E41: =IF(B41=0,0,(COUNTIFS(Incident_Data!$K$2:$K$181,A41,Incident_Data!$D$2:$D$181,"Critical")+COUNTIFS(Incident_Data!$K$2:$K$181,A41,Incident_Data!$D$2:$D$181,"High"))/B41) -> 0.39393939 | F41: =IFERROR(COUNTIFS(Incident_Data!$K$2:$K$181,A41,Incident_Data!$P$2:$P$181,"Yes")/(COUNTIFS(Incident_Data!$K$2:$K$181,A41,Incident_Data!$P$2:$P$181,"Yes")+COUNTIFS(Incident_Data!$K$2:$K$181,A41,Incident_Data!$P$2:$P$181,"No")),0) -> 0.33333333
A42: Endpoint Security | B42: =COUNTIF(Incident_Data!$K$2:$K$181,A42) -> 28 | C42: =SUMIF(Incident_Data!$K$2:$K$181,A42,Incident_Data!$I$2:$I$181) -> 1528133 | D42: =IF(B42=0,0,C42/B42) -> 54576.179 | E42: =IF(B42=0,0,(COUNTIFS(Incident_Data!$K$2:$K$181,A42,Incident_Data!$D$2:$D$181,"Critical")+COUNTIFS(Incident_Data!$K$2:$K$181,A42,Incident_Data!$D$2:$D$181,"High"))/B42) -> 0.32142857 | F42: =IFERROR(COUNTIFS(Incident_Data!$K$2:$K$181,A42,Incident_Data!$P$2:$P$181,"Yes")/(COUNTIFS(Incident_Data!$K$2:$K$181,A42,Incident_Data!$P$2:$P$181,"Yes")+COUNTIFS(Incident_Data!$K$2:$K$181,A42,Incident_Data!$P$2:$P$181,"No")),0) -> 0.52941176
A43: Data Protection | B43: =COUNTIF(Incident_Data!$K$2:$K$181,A43) -> 27 | C43: =SUMIF(Incident_Data!$K$2:$K$181,A43,Incident_Data!$I$2:$I$181) -> 1452637 | D43: =IF(B43=0,0,C43/B43) -> 53801.37 | E43: =IF(B43=0,0,(COUNTIFS(Incident_Data!$K$2:$K$181,A43,Incident_Data!$D$2:$D$181,"Critical")+COUNTIFS(Incident_Data!$K$2:$K$181,A43,Incident_Data!$D$2:$D$181,"High"))/B43) -> 0.33333333 | F43: =IFERROR(COUNTIFS(Incident_Data!$K$2:$K$181,A43,Incident_Data!$P$2:$P$181,"Yes")/(COUNTIFS(Incident_Data!$K$2:$K$181,A43,Incident_Data!$P$2:$P$181,"Yes")+COUNTIFS(Incident_Data!$K$2:$K$181,A43,Incident_Data!$P$2:$P$181,"No")),0) -> 0.5625
A44: Security Awareness | B44: =COUNTIF(Incident_Data!$K$2:$K$181,A44) -> 28 | C44: =SUMIF(Incident_Data!$K$2:$K$181,A44,Incident_Data!$I$2:$I$181) -> 1065731 | D44: =IF(B44=0,0,C44/B44) -> 38061.821 | E44: =IF(B44=0,0,(COUNTIFS(Incident_Data!$K$2:$K$181,A44,Incident_Data!$D$2:$D$181,"Critical")+COUNTIFS(Incident_Data!$K$2:$K$181,A44,Incident_Data!$D$2:$D$181,"High"))/B44) -> 0.39285714 | F44: =IFERROR(COUNTIFS(Incident_Data!$K$2:$K$181,A44,Incident_Data!$P$2:$P$181,"Yes")/(COUNTIFS(Incident_Data!$K$2:$K$181,A44,Incident_Data!$P$2:$P$181,"Yes")+COUNTIFS(Incident_Data!$K$2:$K$181,A44,Incident_Data!$P$2:$P$181,"No")),0) -> 0.47368421
A45: Network Resilience | B45: =COUNTIF(Incident_Data!$K$2:$K$181,A45) -> 19 | C45: =SUMIF(Incident_Data!$K$2:$K$181,A45,Incident_Data!$I$2:$I$181) -> 1061329 | D45: =IF(B45=0,0,C45/B45) -> 55859.421 | E45: =IF(B45=0,0,(COUNTIFS(Incident_Data!$K$2:$K$181,A45,Incident_Data!$D$2:$D$181,"Critical")+COUNTIFS(Incident_Data!$K$2:$K$181,A45,Incident_Data!$D$2:$D$181,"High"))/B45) -> 0.42105263 | F45: =IFERROR(COUNTIFS(Incident_Data!$K$2:$K$181,A45,Incident_Data!$P$2:$P$181,"Yes")/(COUNTIFS(Incident_Data!$K$2:$K$181,A45,Incident_Data!$P$2:$P$181,"Yes")+COUNTIFS(Incident_Data!$K$2:$K$181,A45,Incident_Data!$P$2:$P$181,"No")),0) -> 0.33333333
...

Sheet CISO_Board_Insights
A1: GRC102 Week 3 — Part D3: Three Critical Insights for the CISO
A2: Each insight below is drawn directly from the Core_Analysis and Advanced_Analysis sheets and is cross-referenced to the underlying table.
A4: # | B4: Finding | C4: Supporting Data (source table) | D4: Governance Significance | E4: Accountable / Responsible Role(s) | F4: Recommended Action, Owner & KPI
A5: 1 | B5: High and Critical severity incidents breach their resolution SLA far more often than Medium or Low severity incidents (73.5% and 70.6% breach rates respectively, vs 34.7% for Medium and 0% for Low, among resolved incidents). | C5: Advanced_Analysis, Table 1 (SLA breach by Severity) | D5: The incidents that matter most for regulatory and Board exposure are also the ones most likely to run late, which directly undermines the credibility of the escalation-timing commitments used in the material cyber-risk escalation workflow. | E5: Accountable: CISO. Responsible: IT Security and SOC (highest-volume responders); CRO consulted on risk-acceptance of repeat SLA misses. | F5: Action: introduce a mandatory management review for any Critical/High incident forecast to breach SLA at the 50% elapsed-time mark. Owner: CISO's governance secretariat. KPI: Critical/High SLA breach rate reduced below 40% within two quarters.
A6: 2 | B6: Incidents involving a third party cost 42% more on average than incidents with no third-party involvement (approx. $73,700 vs $52,000) and are escalated to Board/Executive level slightly more often (13.9% vs 10.2%). | C6: Advanced_Analysis, Table 4 (Third-party involvement) | D6: Third-party risk is not confined to the Third-Party Risk control domain on paper; it is a material cost and escalation driver in practice, which strengthens the case for centralising third-party risk acceptance rather than leaving it to individual business units. | E6: Accountable: CRO / Risk (risk acceptance) and Legal (contractual exposure). Responsible: Procurement and the CISO's Third-Party Risk Working Group. | F6: Action: require CISO-office security review before contract signature for any vendor with data or system access, independent of the requesting business unit. Owner: Head of Third-Party Risk Working Group. KPI: 100% of new material vendor contracts carry a completed security review before signature.
A7: 3 | B7: Identity & Access Management is the largest single control domain by incident volume (33 incidents) and total cost impact ($1.93m), while the smaller Privileged Access & Monitoring domain has the highest average cost per incident (~$138,500) and the highest severity concentration (100% Critical/High) of any domain. | C7: Advanced_Analysis, Table 5 (Control_Domain scorecard) | D7: Access-related control weaknesses are NDPC's single largest quantifiable governance exposure, and the small number of privileged-access incidents disproportionately drives severe outcomes, indicating that access governance (RACI activity: Privileged access approval) is under-resourced relative to its risk contribution. | E7: Accountable: CISO. Responsible: IAM team and IT. Consulted: Internal Audit for independent testing of access controls. | F7: Action: commission an independent review of privileged-access approval and recertification controls within the next quarter, with quarterly access recertification thereafter. Owner: IAM Team Lead, reporting to CISO. KPI: privileged-access incidents reduced and 100% of privileged accounts recertified each quarter.
